Workbook

Sheet Introduction
B1: Tesco PLC - DCF Rufus Cottle 31/7/26
B3: This part of my personal project is to perform a DCF on Tesco PLC to pair with my COMPS valuation . I think this is important as COMPS tell you what the market values similar companies to the target company however the DCF offers a intrinsic value based on what the target company cash flows will look like in the future.
B5: Contents:
B6: 2. WACC - builds a discount factor
B7: 3. DCF + sensitivity- the valuation
B8: 4. Valuation
B9: 5. Valuation summary
B12: Sources:
B13: Tesco annual report - https://www.tescoplc.com/investors/reports-results-and-presentations/annual-report-2025
B14: Gilt source - https://www.hl.co.uk/shares/corporate-bonds-gilts/bond-prices/uk-gilts
B15: Bond YTM source - https://www.tescoplc.com/investors/debt-investors/unsecured-bonds
B16: Beta source - https://uk.investing.com/pro/LSE:TSCO/explorer/beta

Sheet WACC
B2: WACC | K2: What this slide does:
K3: Everything on this tba exists to produce a number called the discount rate. The DCF will forecast Tesco's future cash and then shrink each year back to todays value and the rate we use to do this is called the discount rate. We use the weighted average cost of capital also referred to as the WACC. It's the blended return Tesco's funders (which are a mix of lenders and shareholders) demand. so it is the hurdle those future cash flows must clear to be worth anything.
K4: Cost of equity:
B5: Cost of equity (CAPM) | K5: This is what the shareholders demand however since equity has no contract as the shareholders are not promised a return in the same way lenders are, you can't read of how much they demand in return from a document. You have to estimate it with CAPM. This builds the demanded return into 3 layers. 1. The risk fee rate is what you earn with zero risk. This is here as every investors base line alternative without taking on any risk is lending to the government such as a 10 year gilt. 2. The Beta is a number not a return and this number measures how much a specific stock loves relative to the market. so if you have a beta of 1 the stock moves the same amount as the market. 3. The equity risk premium (ERP) is the extra return demanded for taking an equity risk.
B6: Risk free rate (rf) | C6: 0.0504
B7: Beta | C7: 0.58
B8: Equity risk premium (ERP) | C8: 0.05
B9: Cost of equity (Re) | C9: =(C6+C7*C8) -> 0.0794
B10: Cost of debt | K10: Cost of debt :
K11: This is what lenders demand and we can just read it off their contracts through 2 methods. 1. The YTM on a 10 year Tesco bond or 2. Take the risk free rate then add the credit spread ( Tesco is BBB). We then know of the cost of debt before tax so we then have to take the tax benefits into account. Unlike paying shareholders, paying lenders on their interest is tax deductible so you have to take out the tax rate out of the cost of debt to get the after tax cost of debt. The tax rate for corporations in the UK is 25%. As the interest is tax deductible, the borrowing cuts Tesco's tax bill so the tax man effectively re funds part of the interest.
B12: Pre-tax cost of debt (rd) | C12: 0.0634
B13: Tax rate | C13: 0.25
B14: After tax cost of debt | C14: =(C12*(1-C13)) -> 0.04755
K15: Capital structure : WACC is an average of the 2 costs but not a straight average as most companies wont have a 50/50 split of equity and debt. So a company which is 90% equity funded should have a WACC that's mostly cost of equity.
B16: Capital structure
B17: Equity value | C17: 32151
B18: Total debt | C18: 14666
B19: Total funding | C19: =(C17+C18) -> 46817
B20: Equity share | C20: =(C17/C19) -> 0.68673772
B21: Debt share | C21: =(C18/C19) -> 0.31326228
K22: WACC : This formula to work out the WACC in words is just the equity's weight x cost of equity + debt's weight x after tax cost of debt. Which is each funder's cost scaled by how much of the company they fund.
B23: WACC
B24: WACC | C24: =(C20*C9+C21*C12*(1-C13)) -> 0.069422596

Sheet Free Cash Flow
K1: What this tab does:
K2: This tab forecast how much actual cash tesco makes per year which is what the DCF actually discounts. The slide builds unlevered free cash flows which is the cash made by the business before paying any financing costs so this cash belongs to all funders (Lenders and stockholders) which is why it gets discounted back at the WACC to give the enterprise value. This tabs information comes from assumptions not set facts like the WACC tab as each assumption comes from Tescos's real historical from the annual report
B4: Assumptions/ Drivers | K4: Assumptions/Drivers :
K5: These are how we get the values to forecast. Revenue growth sits at the top because revenue is the top of the waterfall, with every line below being worked out from it. EBIT margin is included to show how much of the sales is turned into operating profit. D&A % is included because you have to add it back on later. Capex % is cash spent on stores and equipment so affects the unlevered cash flow as well. Change in NWC % is included to show all the cash tied up in day to day operations so changes the unlevered cash flow. Tax rate is pulled directly from the WACC tab.
B6: Base year revenue (£m) | C6: 69916
D8: Year 1 | E8: Year 2 | F8: Year 3 | G8: Year 4 | H8: Year 5
B9: Revenue growth % | D9: 0.025 | E9: 0.025 | F9: 0.025 | G9: 0.025 | H9: 0.025
B10: EBIT margin % | D10: 0.045 | E10: 0.045 | F10: 0.045 | G10: 0.045 | H10: 0.045
B11: D&A (% of revenue) | D11: 0.025 | E11: 0.025 | F11: 0.025 | G11: 0.025 | H11: 0.025
B12: Capex (% of revenue) | D12: 0.022 | E12: 0.022 | F12: 0.022 | G12: 0.022 | H12: 0.022
B13: Change in NWC (% of revenue) | D13: 0.012 | E13: 0.012 | F13: 0.012 | G13: 0.012 | H13: 0.012
B14: Tax rate (From WACC tab) | D14: =WACC!C13 -> 0.25 | E14: =WACC!C13 -> 0.25 | F14: =WACC!C13 -> 0.25 | G14: =WACC!C13 -> 0.25 | H14: =WACC!C13 -> 0.25
B16: Unlevered Free Cash Flow | K16: Unlevered Free Cash flow :
D17: Year 1 | E17: Year 2 | F17: Year 3 | G17: Year 4 | H17: Year 5 | K17: Revenue = base year grown by the growth %, then each later year grow off the year before it. EBIT = revenue x margin, the slice of sales that becomes operating profit. This in unlevered cash flow so we assume Tesco has no debt at all meaning there is no interest to deduct so no tax shield either. The shield is already handled in the WACC so if you taxed the profit after interest here it would be counting the benefit of debt twice. once in the cash flows and once in the discount rate. Therefore taxing the whole EBIT keeps the model from double counting the tax benefit. The result of removing the tax from the EBIT is NOPAT (after tax operating profit). D&A was taken out when working out the EBIT because it is an expense in the accounts however no actual cash leaves the business for depreciation, its just an accounting charge that spreads the cost of an asset over its life. However since we are building a cash figure we have to add it back turning profit into cash. Capex is real cash spent buying long term assets like stores and equipment. Its not inside EBIT so it has to be taken into account here. Change in NWC also needs to be taken into account to work out unlevered cash flow since it effects cash flow as it shows the cash tied up in the day to day operations such as inventory and trade receivables. However grocers can actually be negative here as they collect from customers before payer their suppliers so cash is released instead. When you have done all this to the EBIT you will then have your unlevered cash flow = NOPAT + D&A - Capex - change in NWC. This shows the genuine cash the business produces each year before financing.
B18: Revenue | D18: =(C6*(1+D9)) -> 71663.9 | E18: =(D18*(1+E9)) -> 73455.497 | F18: =(E18*(1+F9)) -> 75291.885 | G18: =(F18*(1+G9)) -> 77174.182 | H18: =(G18*(1+H9)) -> 79103.537
B19: EBIT | D19: =(D18*D10) -> 3224.8755 | E19: =(E18*E10) -> 3305.4974 | F19: =(F18*F10) -> 3388.1348 | G19: =(G18*G10) -> 3472.8382 | H19: =(H18*H10) -> 3559.6591
B20: Cash tax | D20: =-D19*D$14 -> -806.21887 | E20: =-E19*E$14 -> -826.37435 | F20: =-F19*F$14 -> -847.03371 | G20: =-G19*G$14 -> -868.20955 | H20: =-H19*H$14 -> -889.91479
B21: NOPAT | D21: =D19+D20 -> 2418.6566 | E21: =E19+E20 -> 2479.123 | F21: =F19+F20 -> 2541.1011 | G21: =G19+G20 -> 2604.6286 | H21: =H19+H20 -> 2669.7444
B22: D&A | D22: =D18*D11 -> 1791.5975 | E22: =E18*E11 -> 1836.3874 | F22: =F18*F11 -> 1882.2971 | G22: =G18*G11 -> 1929.3546 | H22: =H18*H11 -> 1977.5884
B23: Capex | D23: =-D18*D12 -> -1576.6058 | E23: =-E18*E12 -> -1616.0209 | F23: =-F18*F12 -> -1656.4215 | G23: =-G18*G12 -> -1697.832 | H23: =-H18*H12 -> -1740.2778
B24: Change in NWC | D24: =-(D18-$C$6)*D13 -> -20.9748 | E24: =-(E18-D18)*E13 -> -21.49917 | F24: =-(F18-E18)*F13 -> -22.036649 | G24: =-(G18-F18)*G13 -> -22.587565 | H24: =-(H18-G18)*H13 -> -23.152255
B25: Unlevered FCF | D25: =D21+D22+D23+D24 -> 2612.6735 | E25: =E21+E22+E23+E24 -> 2677.9904 | F25: =F21+F22+F23+F24 -> 2744.9401 | G25: =G21+G22+G23+G24 -> 2813.5636 | H25: =H21+H22+H23+H24 -> 2883.9027

Sheet Valuation
B2: Valuation | K2: Discounting block :
K3: This block is used to discount the future cash flows we worked out earlier using the WACC to get the present value of those future cash flows. A pound arriving in the future is worth less than a pound today, because todays pound could be invested to earn the WACC in the meantime. So each year the cash has to be shrunk by the discount factor, which is 1 divided by (1+WACC) raised to the power of how many years in the future you are trying to discount from.
B4: Discounting
B5: WACC (from WACC Tab) | C5: =(WACC!C24) -> 0.069422596
C7: Year 0 | D7: Year1 | E7: Year2 | F7: Year3 | G7: Year4 | H7: Year5
B8: Unlevered FCF | D8: ='Free Cash Flow'!D25 -> 2612.6735 | E8: ='Free Cash Flow'!E25 -> 2677.9904 | F8: ='Free Cash Flow'!F25 -> 2744.9401 | G8: ='Free Cash Flow'!G25 -> 2813.5636 | H8: ='Free Cash Flow'!H25 -> 2883.9027
B9: Discount period | D9: 1 | E9: 2 | F9: 3 | G9: 4 | H9: 5
B10: Discount factor | D10: =1/(1+$C$5)^D9 -> 0.93508404 | E10: =1/(1+$C$5)^E9 -> 0.87438216 | F10: =1/(1+$C$5)^F9 -> 0.8176208 | G10: =1/(1+$C$5)^G9 -> 0.76454416 | H10: =1/(1+$C$5)^H9 -> 0.71491304
B11: PV of Unlevered FCF | D11: =D8*D10 -> 2443.0693 | E11: =E8*E10 -> 2341.587 | F11: =F8*F10 -> 2244.3201 | G11: =G8*G10 -> 2151.0936 | H11: =H8*H10 -> 2061.7397
B12: Sum: PV of forecast FCF | C12: =SUM(D11:H11) -> 11241.81
K13: Terminal value block :
B14: Terminal value | K14: You can only forecast 5 years credibly however Tesco's doesn’t stop in 5 years, it will keep generating cash fore decades. Terminal value captures all of that into a single figure. You compue it in 2 ways and cross check them. Method A the exit multiple method: values Tesco at year 5 as if it was sold at a market EV/EBITDA mulitple. The multiple i used is not Tesco's current 9.2x because cyrrent levels include a premuim that shouldn't/t be baked in forever. Method B is the perpuity growth method which instead assumes the year 5 cash grows a small fixed rate forever where g must be below the WACC or the maths breaks. Both terminal values are measured at year 5 so both get discounted back by the year 5 factor.
B15: Method A - Exit Multiple (EMM)
B16: Terminal year EBITDA | C16: ='Free Cash Flow'!H19+'Free Cash Flow'!H22 -> 5537.2476
B17: Exit EV/EBITDA multiple | C17: 6.5
B18: Terminal value (undiscounted) | C18: =C16*C17 -> 35992.109
B19: PV of terminal value | C19: =C18*H10 -> 25731.228
B21: Method B - Perpetuity Growth (PGM)
B22: Terminal year UFCF | C22: =H8 -> 2883.9027
B23: Terminal growth rate (g) | C23: 0.02
B24: Terminal value (undiscounted) | C24: =C22*(1+C23)/($C$5-C23) -> 59518.944
B25: Pv of terminal value (PGM) | C25: =C24*H10 -> 42550.869
B27: Selected TV method | C27: PGM
B28: PV of terminal value (selected) | C28: =IF(C27="PGM",C25,C19) -> 42550.869
B30: Enterprise value | K30: Enterprise value :
B31: PV of forecast FCF | C31: =C12 -> 11241.81 | K31: This just adds the 2 halves of the answer together, the present value of the forecasted cash flows plus the terminal value leading to a result which is the value of the whole company.
B32: PV of terminal value | C32: =C28 -> 42550.869
B33: Enterprise value (EV) | C33: =C32+C31 -> 53792.679
B35: EV to equity bridge | K35: EV equity bridge:
B36: Enterprise value | C36: =C33 -> 53792.679 | K36: Enterprise value belongs to everyone who funds the firm. To get what the shareholders alone own you have to strip out what the lenders are owed. This is net debt plus anything else ahead of ordinary shareholders like preferred and minority interest. This leaves the equity value which is the value left to the shareholders alone.
B37: Less: net debt | C37: -9454
B38: preferred | C38: 0
B39: Less: minority interest | C39: -4
B40: Equity value | C40: =SUM(C36:C39) -> 44334.679
B42: Per share | K42: Per share:
B43: FD shares (m) | C43: 6840.6 | K43: Equity value divided by fully diluted shares gives an intrinsic value per share. I have then compared my intrinsic value to the current market price of £4.70
B44: Implied share price | C44: =C40/C43 -> 6.4811097
B45: Current share price (£) | C45: 4.7
B46: Implied upside/downside | C46: =C44/C45-1 -> 0.37895951
B50: Sensitivity
...

Sheet Valuation Summary
B4: Method | C4: Implied £
B5: DCF — Perpetuity Growth (base) | C5: =Valuation!C44 -> 6.4811097
B6: DCF — Exit Multiple (cross-check) | C6: 4.02
B7: Sensitivity — low | C7: =MIN(Valuation!D53:H57) -> 4.4043333
B8: Sensitivity — high | C8: =MAX(Valuation!D53:H57) -> 11.37484
B9: Current share price | C9: =Valuation!C45 -> 4.7
B10: Implied upside/(downside) | C10: =Valuation!C46 -> 0.37895951
B13: DCF implies £4.02 (exit multiple) to £6.48 (perpetuity growth), against a market price of £4.70. The methods straddle the current price, and the gap reflects how sensitive the perpetuity approach is to terminal assumptions — terminal value is 79% of enterprise value. Comps on a lease-inclusive basis imply £3.10, suggesting the market is pricing Tesco closer to peer multiples than to its intrinsic cash generation
